{"name": "Test of failed attempt to login with the wrong fields", "status": "failed", "statusDetails": {"message": "AssertionError: Error message contains wrong text\nassert '{\"code\":404,... не найдена\"}' == '\"message\": \"...ь не найдена\"'\n  \n  - \"message\": \"Учетная запись не найдена\"\n  ?           -\n  + {\"code\":404,\"message\":\"Учетная запись не найдена\"}\n  ? ++++++++++++                                     +", "trace": "self = <tests.test_courier_login.TestCourierLogin object at 0x000002548FF76E90>, new_courier = (<Response [201]>, ['lsuqwtkqgc', 'vpdgopeqdt', 'peagtimxxx']), wrong_field = 'login'\n\n    @allure.title('Test of failed attempt to login with the wrong fields')\n    @allure.description('Negative test of the endpoint \"Логин курьера в системе\" POST /api/v1/courier/login.'\n                        'Parameterized test, checks impossibility of authorization '\n                        'when any of the mandatory fields is wrong')\n    @pytest.mark.parametrize(\"wrong_field\", [\"login\", \"password\"])\n    def test_login_with_any_wrong_field_failed(self, new_courier, wrong_field):\n        login_pass = new_courier[1]\n        payload = {\n            \"login\": login_pass[0],\n            \"password\": login_pass[1]\n        }\n        payload[wrong_field] = f'{payload[wrong_field]}a'\n        response = requests.post(f'{url}/api/v1/courier/login', data=payload)\n        assert response.status_code == 404, f'Instead of an error code 404 received code {response.status_code}'\n>       assert response.text == '\"message\": \"Учетная запись не найдена\"', f'Error message contains wrong text'\nE       AssertionError: Error message contains wrong text\nE       assert '{\"code\":404,... не найдена\"}' == '\"message\": \"...ь не найдена\"'\nE         \nE         - \"message\": \"Учетная запись не найдена\"\nE         ?           -\nE         + {\"code\":404,\"message\":\"Учетная запись не найдена\"}\nE         ? ++++++++++++                                     +\n\ntests\\test_courier_login.py:54: AssertionError"}, "description": "Negative test of the endpoint \"Логин курьера в системе\" POST /api/v1/courier/login.Parameterized test, checks impossibility of authorization when any of the mandatory fields is wrong", "parameters": [{"name": "wrong_field", "value": "'login'"}], "start": 1717844834734, "stop": 1717844834888, "uuid": "16cc17f1-5ae3-4610-8cc9-fa99ce68d729", "historyId": "232207e8de485095a45435a34197cc90", "testCaseId": "67167e8a3582672514a127bcef0528c3", "fullName": "tests.test_courier_login.TestCourierLogin#test_login_with_any_wrong_field_failed", "labels": [{"name": "parentSuite", "value": "tests"}, {"name": "suite", "value": "test_courier_login"}, {"name": "subSuite", "value": "TestCourierLogin"}, {"name": "host", "value": "DESKTOP-4KK18J8"}, {"name": "thread", "value": "44264-MainThread"}, {"name": "framework", "value": "pytest"}, {"name": "language", "value": "cpython3"}, {"name": "package", "value": "tests.test_courier_login"}]}